Workbook

Sheet Epicas
A1: Épica | B1: ID HU | C1: Nombre | D1: Enunciado de la Historia de Usuario | E1: Criterios de Aceptación
A2: Formulario de registro | B2: HU09 | C2: Registro de nuevo usuario | D2: Como paciente Quiero registrarme mediante un formulario que solicite mis datos personales y de contacto, incluyendo aceptación de términos y condiciones Para poder acceder al sistema con una cuenta propia. | E2: - El formulario debe solicitar como mínimo: tipo y número de documento, nombre, apellido, teléfono, género, correo electrónico, contraseña y confirmación de contraseña. - El botón de "Registrarme" debe estar deshabilitado hasta que todos los campos obligatorios estén diligenciados y se acepten los términos y condiciones. - El usuario debe marcar la casilla de aceptación de términos y condiciones para completar el registro. - Una vez registrado, el paciente es redirigido automáticamente a la página de inicio de sesión o a su panel principal. - Debe haber un enlace claramente visible con el texto “¿Ya tienes una cuenta? Inicia sesión”. - Al hacer clic en el enlace, debe redirigirme correctamente al formulario de inicio de sesión. - Cada campo debe mostrar retroalimentación inmediata si el valor ingresado no cumple con el formato esperado (por ejemplo, correo mal escrito). - Los mensajes de error deben ser claros y específicos para cada campo. - No se permite enviar el formulario si hay errores de validación sin corregir, y se le indica al usuario qué campos debe revisar. - La contraseña debe tener mínimo 8 caracteres, al menos una mayúscula, un número y un símbolo. - Si no cumple con los requisitos, debe mostrarse un mensaje de advertencia y no permitir el registro | G2: las epicas son como grandes metas de negocio o volumenes de trabajo las cuales contienen una o varias historias de usuario
A4: Formulario de inicio de sesion | B4: HU12 | C4: Acceder con cuenta existente | D4: Como paciente Quiero poder iniciar sesión en el sistema utilizando mi correo y mi contraseña Para acceder a mi perfil y funcionalidades del sistema médico. | E4: − El formulario debe aceptar como identificador el correo electrónico o el número de teléfono registrado. − Si las credenciales son correctas, el usuario debe ser redirigido automáticamente al panel principal del sistema. − Si las credenciales son correctas, el paciente es redirigido a su panel principal.
B5: HU13 | C5: Recuperación de contraseña | D5: Como paciente Quiero contar con una opción para recuperar mi contraseña en caso de olvidarla Para poder restablecer mi acceso al sistema. | E5: − Debe haber un enlace visible (ej. "¿Olvidaste tu contraseña?") en la pantalla de inicio de sesión. − Debe haber un enlace visible con el texto “¿Olvidaste tu contraseña?” en el formulario de inicio de sesión. − Al ingresar un correo registrado, el sistema debe enviar un correo con instrucciones para restablecer la contraseña. − El enlace/código debe tener una caducidad por seguridad.
B6: HU11 | C6: Notificación por error del servidor en inicio de sesión | D6: Como paciente Quiero recibir un mensaje claro si al intentar iniciar sesión el servidor está caído o hay un problema técnico Para saber que el error no es mío. | E6: − Si hay error del servidor (código 500 o similar), debe mostrarse un mensaje como “Servicio no disponible, por favor intenta más tarde”. − El sistema no debe eliminar los datos ingresados en el formulario al producirse el error.
A8: Validaciones de formularios | B8: HU10 | C8: Alerta por correo duplicado en registro | D8: Como paciente Quiero ser notificado si intento registrar una cuenta con un correo ya existente Para saber que debo iniciar sesión en lugar de crear una nueva cuenta. | E8: − Si el correo ya está registrado, debe mostrarse un mensaje como “Este correo ya está vinculado a una cuenta. ¿Deseas iniciar sesión?”. − El sistema debe bloquear el registro hasta que se ingrese un correo no registrado.
A10: Menu | B10: HU01 | C10: Menú de navegación clara | D10: Como paciente Quiero que el sistema tenga categorías claras en el menú Para poder navegar fácilmente sin perderme. | E10: − El menú debe estar visible en todo momento mientras el usuario navega. − Cada opción del menú debe redirigir correctamente a la sección correspondiente. − Deben existir las categorías
A12: Panel principal | B12: HU02 | C12: Panel de resumen del paciente | D12: Como paciente Quiero ver un panel principal con un resumen de mis próximas citas, indicaciones médicas y notificaciones recientes Para tener un panorama general desde que ingreso al sistema. | E12: − El resumen debe incluir al menos: fecha y hora de la próxima cita, últimas indicaciones, y las tres notificaciones más recientes. − Debe mostrarse automáticamente al ingresar al sistema sin necesidad de navegar a otra sección. − Las notificaciones recientes (ej. recordatorios de citas, actualizaciones) son visibles en el panel principal. − El panel carga toda la información en menos de 3 segundos.
B13: HU03 | C13: Panel diario del médico | D13: Como médico Quiero contar con un panel donde pueda visualizar mis citas del día y acceder al historial médico de cada paciente agendado Para preparar mejor mi jornada laboral. | E13: − El panel debe mostrar las citas ordenadas por hora. − Cada cita debe permitir acceso rápido al historial médico del paciente. − El historial médico del paciente debe incluir citas previas, diagnósticos, indicaciones y medicamentos recetados. − El panel del médico se actualiza en tiempo real con nuevas citas o cancelaciones.
A15: Pie de pagina | B15: HU58 | C15: Mostrar pie de página con información esencial en cada sección | D15: Como paciente Quiero que en cada sección del sistema se muestre un pie de página con la información esencial de la institución Para tener a la mano datos importantes sin importar dónde esté en el sistema. | E15: − El pie de página se muestra de forma consistente en todas las secciones del sistema. − Contiene datos básicos como el nombre de la institución, año y derechos reservados.
A17: Gestión de Notificaciones | B17: HU41 | C17: Recibir recordatorio de cita próxima | D17: Como paciente Quiero recibir una alerta cuando tenga una cita cercana (por ejemplo, un día antes), Para no olvidarla. | E17: - El sistema debe enviar una notificación (por correo o dentro de la plataforma) 24 horas antes de la cita. − Si el paciente tiene la app móvil o el navegador habilitado, también debe mostrarse una notificación push
B18: HU54 | C18: Acceder en todo momento a las notificaciones | D18: Como paciente Quiero tener una opción visible en todo momento para acceder a mis notificaciones, Para estar informado de cualquier novedad del sistema. | E18: - El icono de notificaciones es visible en todas las pantallas del sistema mientras el paciente esté autenticado. − Al hacer clic en el icono, se despliega una lista de notificaciones recientes.
B19: HU55 | C19: Ver información detallada o redirección desde la notificación | D19: Como paciente Quiero poder ver en detalle la información de cada notificación o que me redirija a la sección relacionada Para comprender mejor su contenido. | E19: − Al hacer clic en una notificación, el sistema muestra información detallada o redirige automáticamente a la sección relacionada. − La notificación se marca como leída después de haber sido visualizada o redirigida.
B20: HU56 | C20: Eliminar una notificación individual | D20: Como paciente Quiero tener una opción para eliminar notificaciones individuales (por ejemplo, con un ícono de bote de basura) Para mantener limpia mi bandeja de notificaciones. | E20: - Cada notificación cuenta con un ícono visible (como una papelera) para eliminarla. − Al eliminarla, el sistema actualiza la lista y muestra un mensaje de confirmación.
B21: HU57 | C21: Eliminar todas las notificaciones en una sola acción | D21: Como paciente Quiero tener una opción para eliminar todas mis notificaciones de una sola vez Para ahorrar tiempo y evitar hacerlo una por una. | E21: − El paciente puede hacer clic en un botón “Eliminar todas” para borrar todas sus notificaciones. − El sistema solicita confirmación antes de eliminar todas las notificaciones y muestra un mensaje de éxito tras la acción.
A23: Gestion tecnica | B23: HU04 | C23: Soporte técnico o FAQ | D23: Como paciente Quiero tener acceso a un chat de soporte o una sección de preguntas Frecuentes Para recibir ayuda si tengo problemas usando el sistema. | E23: - Debe existir un enlace visible en el menú o pie de página hacia la sección de ayuda. - Si hay chat, este debe permitir interacción en tiempo real o, en su defecto, dejar un mensaje. - Las FAQ deben estar organizadas por categorías para facilitar la búsqueda de información. - El chat de soporte debe permitir al paciente iniciar una conversación con un agente de soporte. - Debe existir un botón visible etiquetado como “Atención al paciente” o similar. - Al hacer clic, se debe mostrar una lista con los medios disponibles (chat, teléfono, correo, etc.) y su horario de atención. - La información de contacto debe ser precisa y funcional durante los horarios de atención. - Debe existir un formulario accesible desde el menú o la pantalla principal. - Al enviar la queja o sugerencia, el sistema debe mostrar un mensaje de confirmación. - Al enviar el formulario, el paciente debe recibir una confirmación de envío y, opcionalmente, un número de seguimiento. - El sistema debe registrar y notificar al equipo administrativo sobre la nueva queja/reclamo.
B24: HU05 | C24: Reporte de errores técnicos | D24: Como paciente Quiero poder reportar un error técnico desde cualquier pantalla del sistema Para notificar fácilmente si algo no funciona correctamente | E24: − Debe haber un botón visible tipo “Reportar un problema” en todas las vistas del sistema. − Al enviar el reporte, debe mostrarse una notificación de confirmación de envío exitoso.
A27: Perfil | B27: HU51 | C27: Acceder a un menú desplegable con opciones del perfil | D27: Como paciente Quiero tener acceso a un contenedor o menú desplegable desde mi perfil Para gestionar mis opciones personales dentro del sistema. | E27: − El paciente puede hacer clic en su foto o nombre de perfil para desplegar un menú con opciones como "Editar perfil", "Cerrar sesión", entre otras. − El menú desplegable permanece visible hasta que el paciente seleccione una opción o haga clic fuera del menú.
B28: HU52 | C28: Editar mis datos personales desde el perfil | D28: Como paciente Quiero poder modificar mis datos personales (como teléfono, dirección, correo) desde el menú de perfil Para mantener mi información actualizada. | E28: - El paciente puede acceder a un formulario desde el menú de perfil para modificar datos como teléfono, dirección y correo electrónico. - Al guardar los cambios, el sistema actualiza la información y muestra un mensaje de confirmación. - El sistema debe validar la nueva contraseña con una política de seguridad mínima (mínimo 8 caracteres, una mayúscula, un símbolo). - El usuario debe recibir una notificación de cambio exitoso.
B29: HU53 | C29: Cerrar sesión desde el menú de perfil | D29: Como paciente Quiero poder cerrar sesión desde el contenedor del perfil Para finalizar mi actividad de forma segura. | E29: - El paciente puede seleccionar la opción "Cerrar sesión" desde el menú desplegable del perfil. - Al cerrar sesión, el sistema redirige automáticamente a la página de inicio de sesión. - Al cerrar sesión, el sistema muestra un mensaje como "Sesión cerrada exitosamente". - El mensaje desaparece automáticamente después de unos segundos o al hacer clic en "Aceptar". 'Epicas'
A31: Notificaciones | B31: HU07 | C31: Configuración de notificaciones | D31: Como paciente Quiero poder elegir qué tipo de notificaciones deseo recibir (correo) Para evitar recibir información no deseada. | E31: − Debe existir una opción en el perfil del paciente para seleccionar los canales de notificación. − Las preferencias deben guardarse correctamente y respetarse al momento de enviar notificaciones.
A33: Atención al usuario | B33: HU15 | C33: Instrucciones o videotutoriales | D33: Como paciente Quiero acceder a una sección con instrucciones o videotutoriales sobre el uso del sistema Para aprender cómo navegar correctamente por la plataforma. | E33: − Debe haber una opción visible llamada “¿Cómo usar el sistema?” o similar. − Al ingresar, deben mostrarse al menos tres recursos (videos, guías escritas, preguntas frecuentes). − Los tutoriales deben ser claros, concisos y fáciles de entender, con una duración máxima de 2-3 minutos por video.
A35: Alertas | B35: HU18 | C35: Alerta por página no disponible | D35: Como paciente Quiero que el sistema me muestre una notificación si accedo a una página inexistente o rota Para poder volver fácilmente al inicio o a una sección válida | E35: − Al acceder a una ruta inválida, debe mostrarse una página 404 amigable con un botón para volver al inicio. − El mensaje debe incluir un texto claro como “Página no encontrada”. − Debe incluir un enlace claro para regresar a la página de inicio o a la última página visitada.
B36: HU34 | C36: Alerta por error técnico al cargar médicos | D36: Como paciente Quiero que el sistema me notifique si no puede cargar la lista de médicos disponibles, Para saber que hay un problema técnico. | E36: −Si ocurre un error de carga, debe mostrarse un mensaje como “No se pudo cargar la lista de médicos. Intenta nuevamente más tarde.” − El sistema debe ofrecer la opción de recargar o regresar a los filtros.
A38: Novedades | B38: HU14 | C38: Visualizar novedades institucionales | D38: Como paciente Quiero ver un apartado con noticias, novedades, proyectos, tutoriales y otras actividades relacionadas con la institución médica Para mantenerme informado. | E38: − Debe mostrarse una sección destacada en la pantalla principal con las últimas 5 noticias o novedades. − Cada ítem debe incluir título, fecha y un resumen o enlace para más información. − Cada noticia debe ser clicable para ver el contenido completo en una nueva vista o modal.
B39: HU17 | C39: Mensaje ante error de carga de noticias | D39: Como paciente Quiero que el sistema me muestre un mensaje si las noticias o novedades no se pueden cargar Para saber que no es un error de mi dispositivo. | E39: − Si hay error en la carga de noticias, debe aparecer un mensaje como “No se pueden mostrar las novedades en este momento”. − El sistema debe intentar recargar automáticamente la sección cada cierto tiempo o permitir al usuario hacerlo manualmente.
A41: Navegacion | B41: HU16 | C41: Navegación con miga de pan | D41: Como paciente Quiero poder navegar a través del sistema utilizando una miga de pan Para saber en qué sección me encuentro y regresar fácilmente a una anterior. | E41: − En cada página interna del sistema, debe mostrarse la miga de pan con la ruta actual. − Cada elemento debe ser clickeable y llevar correctamente a su respectiva sección. − Al hacer clic en cualquier parte de la miga de pan, el usuario debe ser llevado a esa sección anterior de forma correcta.
A43: Calendario | B43: HU19 | C43: Visualizar calendario para agendar citas | D43: Como paciente Quiero acceder a un calendario donde pueda ver los días disponibles Para seleccionar cuándo deseo agendar una cita médica. | E43: − El calendario debe mostrar los días del mes actual y permitir avanzar a meses siguientes. − Los días disponibles deben estar marcados visualmente (por ejemplo, en verde) y los ocupados en gris. − El calendario debe ser interactivo y permitir la navegación entre meses/años.
B44: HU20 | C44: Ver días ocupados en el calendario | D44: Como paciente Quiero ver qué días ya están totalmente ocupados Para evitar seleccionar días sin disponibilidad. | E44: − Los días ocupados deben estar deshabilitados o con un ícono que indique que no hay horarios disponibles. − Si se intenta hacer clic en un día sin disponibilidad, debe aparecer un mensaje informativo.
B45: HU25 | C45: Visualizar horarios no disponibles | D45: Como paciente Quiero que se me muestren claramente los horarios ya tomados Para no intentar agendar en ellos. | E45: − Los horarios no disponibles deben aparecer en gris, tachados o deshabilitados. − El sistema no debe permitir agendar una cita en una hora ya ocupada.
A47: Citas automaticas | B47: HU21 | C47: Agendamiento automático de citas | D47: Como paciente Quiero tener una opción para que el sistema asigne automáticamente una cita disponible según mis preferencias Para ahorrar tiempo. | E47: − El sistema debe permitir seleccionar filtros previos como especialidad y sede antes de asignar automáticamente. − Al generar la cita automática, debe mostrarse un resumen con la opción de confirmarla o rechazarla.
A49: Gestion de citas | B49: HU22 | C49: Filtrar citas por especialidad médica | D49: Como paciente Quiero poder filtrar las citas por especialidad médica Para encontrar más fácilmente al profesional que necesito. | E49: − Debe haber un campo desplegable con la lista de especialidades disponibles. − Al seleccionar una especialidad, deben mostrarse únicamente los médicos que la ofrecen.
B50: HU23 | C50: Selección de hora en un día específico | D50: Como paciente Quiero elegir la hora exacta en la que deseo agendar mi cita Para ajustarla a mi disponibilidad. | E50: − Una vez seleccionado un día, debe desplegarse una lista con los horarios disponibles. − Las horas ocupadas deben estar deshabilitadas o marcadas como no seleccionables.
B51: HU24 | C51: Filtro por ubicación o sede | D51: Como paciente Quiero poder elegir la sede donde quiero recibir atención médica Para escoger la más cercana o conveniente. | E51: − Debe mostrarse una lista de sedes disponibles al momento de agendar. − Al seleccionar una sede, deben filtrarse los médicos y horarios correspondientes a esa sede.
B52: HU26 | C52: Definir rango de horas para buscar médicos | D52: Como paciente Quiero establecer un rango de horas en el que deseo ser atendido Para que el sistema me sugiera médicos dentro de ese horario. | E52: − Debe existir una opción para ingresar un rango de horas (ej. de 8:00 a 11:00 a.m.). − Al aplicar el rango, solo deben mostrarse las opciones de cita que estén dentro de ese intervalo.
B53: HU35 | C53: Cancelar o reprogramar cita | D53: Como paciente Quiero poder cancelar o reprogramar una cita ya agendada Para ajustarla a mis imprevistos o cambios de agenda. | E53: − Debe haber un botón de “Modificar cita” en la sección de historial. − Si la reprogramación se hace con menos de 24 horas de anticipación, debe mostrarse una advertencia o bloquear la acción según política.
A55: Gestion de medicos | B55: HU30 | C55: Ver médicos disponibles después de agendar | D55: Como paciente Quiero que, al completar la información inicial para la cita, el sistema me muestre los médicos disponibles Para seleccionar el que prefiera. | E55: − Una vez elegidos los filtros (fecha, sede, especialidad), deben mostrarse los perfiles de los médicos disponibles. − Cada perfil debe incluir nombre, especialidad y horario de atención.
B56: HU31 | C56: Visualizar perfil del médico | D56: Como paciente Quiero acceder al perfil de un médico antes de seleccionarlo Para conocer más sobre su formación y especialidad. | E56: − Cada médico en la lista debe tener un botón de “Ver perfil”. − El perfil debe mostrar nombre, estudios, especialidad y tipo de atención que ofrece.
B57: HU32 | C57: Seleccionar médico preferido | D57: Como paciente Quiero poder seleccionar al médico que más se ajuste a mis necesidades, y confirmar mi elección con un mensaje claro. | E57: − Al seleccionar un médico, debe mostrarse una ventana emergente confirmando que se ha asignado correctamente. − El sistema debe guardar la relación cita-médico en el historial del paciente.
A59: Gestión de horarios | B59: HU06 | C59: Modificar horarios de médicos | D59: Como administrador Quiero poder modificar horarios a los médicos Para que los mismos sepan las modificaciones o actualizaciones sobre el horario | E59: - Debe existir una vista de calendario editable para cada médico registrado. - Los cambios en la disponibilidad deben reflejarse inmediatamente en el módulo de agendamiento. - Debe existir un apartado para realizar modificaciones a los médicos - Debe existir otro apartado para agregar horarios a médicos - Deben existir médicos registrados - Debe existir una opción al lado del listado de médicos llamada como “Asignar” - Debe permitir establecer un horario con un rango a determinar - Deben existir opciones de hora de inicio y hora de finalización - Debe haber la opción para establecer los días a recibir un horario de trabajo - Debe existir una opción que permita confirmar la acción, titulada “Confirmar” - Debe salir un mensaje de verificación mencionando que la asignación fue exitosa - Debe existir médicos con horarios asignados - Debe existir una opción al lado del listado de médicos titulada “Modificar” - Debe permitir modificar el rango y días de horarios que tenga el médico asignado previamente - Debe incluir una opción que permita enviar la modificación, llamada “Confirmar” - Debe mostrar un mensaje de verificación que la modificación fue existosa.
...

Sheet Product Backlog
A1: # | B1: Historia de Usuario | C1: Valor para el negocio (1-5) | D1: Puntos de Historia | E1: Clasificación KANO | F1: Prioridad (Alta, Media o Baja)
A2: HU01 | B2: Como paciente Quiero que el sistema tenga categorías claras en el menú Para poder navegar fácilmente sin perderme. | C2: 10 | D2: 3 | E2: Must-be | F2: Alta
A3: HU02 | B3: Como paciente Quiero ver un panel principal con un resumen de mis próximas citas, indicaciones médicas y notificaciones recientes Para tener un panorama general desde que ingreso al sistema. | C3: 8 | D3: 5 | E3: Performance | F3: Media
A4: HU03 | B4: Como médico Quiero contar con un panel donde pueda visualizar mis citas del día y acceder al historial médico de cada paciente agendado Para preparar mejor mi jornada laboral. | C4: 10 | D4: 5 | E4: Must-be | F4: Alta
A5: HU04 | B5: Como paciente Quiero tener acceso a un chat de soporte o una sección de preguntas Frecuentes Para recibir ayuda si tengo problemas usando el sistema. | C5: 6 | D5: 3 | E5: Delighter | F5: Baja
A6: HU05 | B6: Como paciente Quiero poder reportar un error técnico desde cualquier pantalla del sistema Para notificar fácilmente si algo no funciona correctamente | C6: 6 | D6: 5 | E6: Must-be | F6: Media
A7: HU06 | B7: Como administrador Quiero poder modificar horarios a los médicos Para que los mismos sepan las modificaciones o actualizaciones sobre el horario | C7: 8 | D7: 5 | E7: Must-be | F7: Alta
A8: HU07 | B8: Como paciente Quiero poder elegir qué tipo de notificaciones deseo recibir (correo) Para evitar recibir información no deseada. | C8: 6 | D8: 5 | E8: Delighter | F8: Baja
A9: HU08 | B9: Como paciente Quiero poder descargar o imprimir un comprobante de mi cita médica Para tenerlo disponible si me lo solicitan o lo necesito. | C9: 7 | D9: 5 | E9: Performance | F9: Media
A10: HU09 | B10: Como paciente Quiero registrarme mediante un formulario que solicite mis datos personales y de contacto, incluyendo aceptación de términos y condiciones Para poder acceder al sistema con una cuenta propia. | C10: 10 | D10: 5 | E10: Must-be | F10: Alta
A11: HU10 | B11: Como paciente Quiero ser notificado si intento registrar una cuenta con un correo ya existente Para saber que debo iniciar sesión en lugar de crear una nueva cuenta. | C11: 7 | D11: 2 | E11: Performance | F11: Media
A12: HU11 | B12: Como paciente Quiero recibir un mensaje claro si al intentar iniciar sesión el servidor está caído o hay un problema técnico Para saber que el error no es mío. | C12: 6 | D12: 5 | E12: Performance | F12: Baja
A13: HU12 | B13: Como paciente Quiero poder iniciar sesión en el sistema utilizando mi correo y mi contraseña Para acceder a mi perfil y funcionalidades del sistema médico. | C13: 10 | D13: 2 | E13: Must-be | F13: Alta
... A60: HU59 | B60: Como administrador Quiero una sección para poder agregar usuarios (medicos, pacientes, y administradores) | C60: 5 | D60: 2 | E60: Must-be | F60: Alta

Sheet Product Backlog - Destacadas
A1: # | B1: Historia de Usuario | C1: Valor para el negocio (1-5) | D1: Puntos de Historia | E1: Clasificación KANO | F1: Prioridad (Alta, Media o Baja)
A2: HU01 | B2: Como paciente Quiero que el sistema tenga categorías claras en el menú (como “Inicio”, “Agendamiento de citas”, “Mi planilla”, “Familiares”, “Indicaciones médicas”, “Configuración”) Para poder navegar fácilmente sin perderme. | C2: 10 | D2: 3 | E2: Must-be | F2: Alta
A3: HU02 | B3: Como paciente Quiero ver un panel principal con un resumen de mis próximas citas, indicaciones médicas y notificaciones recientes Para tener un panorama general desde que ingreso al sistema. | C3: 8 | D3: 5 | E3: Performance | F3: Media
A4: HU03 | B4: Como médico Quiero contar con un panel donde pueda visualizar mis citas del día y acceder al historial médico de cada paciente agendado Para preparar mejor mi jornada laboral. | C4: 10 | D4: 5 | E4: Must-be | F4: Alta
A5: HU04 | B5: Como paciente Quiero tener acceso a un chat de soporte o una sección de preguntas Frecuentes Para recibir ayuda si tengo problemas usando el sistema. | C5: 6 | D5: 3 | E5: Delighter | F5: Baja
A6: HU05 | B6: Como paciente Quiero poder reportar un error técnico desde cualquier pantalla del sistema Para notificar fácilmente si algo no funciona correctamente | C6: 6 | D6: 5 | E6: Must-be | F6: Media
A7: HU06 | B7: Como administrador Quiero poder modificar horarios a los médicos Para que los mismos sepan las modificaciones o actualizaciones sobre el horario | C7: 8 | D7: 5 | E7: Must-be | F7: Alta
A8: HU07 | B8: Como paciente Quiero poder elegir qué tipo de notificaciones deseo recibir (correo) Para evitar recibir información no deseada. | C8: 6 | D8: 5 | E8: Delighter | F8: Baja
A9: HU08 | B9: Como paciente Quiero poder descargar o imprimir un comprobante de mi cita médica Para tenerlo disponible si me lo solicitan o lo necesito. | C9: 7 | D9: 5 | E9: Performance | F9: Media
A10: HU09 | B10: Como paciente Quiero registrarme mediante un formulario que solicite mis datos personales y de contacto, incluyendo aceptación de términos y condiciones Para poder acceder al sistema con una cuenta propia. | C10: 10 | D10: 5 | E10: Must-be | F10: Alta
A11: HU10 | B11: Como paciente Quiero ser notificado si intento registrar una cuenta con un correo ya existente Para saber que debo iniciar sesión en lugar de crear una nueva cuenta. | C11: 7 | D11: 2 | E11: Performance | F11: Media
A12: HU11 | B12: Como paciente Quiero recibir un mensaje claro si al intentar iniciar sesión el servidor está caído o hay un problema técnico Para saber que el error no es mío. | C12: 6 | D12: 5 | E12: Performance | F12: Baja
A13: HU12 | B13: Como paciente Quiero poder iniciar sesión en el sistema utilizando mi correo y mi contraseña Para acceder a mi perfil y funcionalidades del sistema médico. | C13: 10 | D13: 2 | E13: Must-be | F13: Alta
... A60: HU59 | B60: Como administrador Quiero una sección para poder agregar usuarios (medicos, pacientes, y administradores) | C60: 5 | D60: 4 | E60: Must-be | F60: Alta

Sheet Capacidad y Velocidad Equipo
A1: Rol- Perfil | B1: Número Integrantes | C1: Horas diarias | D1: Duración del Sprint | E1: Horas disponibles | F1: Horas Productivas (80%)
A2: Frontend (Juliana) | B2: 1 | C2: 6 | D2: 5 | E2: =C2*D2*B2 -> 30 | F2: =E2*0.8 -> 24
A3: Diseñador (Sofía) | B3: 1 | C3: 6 | D3: 5 | E3: =C3*D3*B3 -> 30 | F3: =E3*0.8 -> 24
A4: Backend (Gerson) | B4: 1 | C4: 6 | D4: 5 | E4: =C4*D4*B4 -> 30 | F4: =E4*0.8 -> 24
A5: QA (Andrés) | B5: 1 | C5: 7 | D5: 5 | E5: =C5*D5*B5 -> 35 | F5: =E5*0.8 -> 28
D6: Capacidad total horas efectiva del sprint | F6: =SUM(F2:F5) -> 100
D7: Velocidad (puntos de historia) | F7: =F6/4 -> 25
A8: Duración del Sprint
A9: 1 semana (5 días hábiles)
A10: 2 semanas (10 días laborables).
A13: Horas disponibles
A14: Cada persona trabaja 8 horas diarias x 5 días = 40 horas por persona x % productividad
A15: Disponibilidad diaria promedio por persona: 6 horas efectivas (considerando reuniones, soporte, etc.).
A17: 6 - 7h × 80% = 6.4 horas efectivas de desarrollo por persona al día
A18: 6.4 horas diarias por persona se irán en actividades necesarias pero no directamente vinculadas a avanzar tareas del Product Backlog.
A19: Reuniones (daily, planning, review, retrospectiva)
A20: Coordinaciones internas
A21: Consultas o bloqueos
A22: Tiempos de espera (por validaciones, revisiones, etc.)
... A29: Velocidad = (Horas disponibles por sprint) ÷ (Horas por punto de historia)

Sheet Sprint Backlog - Antiguo
A1: Sprint | B1: Objetivo | C1: Fecha Inicio | D1: Fecha Fin | E1: ID HU | F1: Historia de Usuario | G1: Puntos de Historia | H1: Prioridad
A2: Sprint 1 | B2: Formulario de registro | C2: Lun 23 jun | D2: Mar 24 jun | E2: HU09 | F2: Como paciente Quiero registrarme mediante un formulario que solicite mis datos personales y de contacto, incluyendo aceptación de términos y condiciones Para poder acceder al sistema con una cuenta propia. | G2: 5 | H2: Alta
B3: Formulario de inicio de sesion | C3: Mar 24 jun | D3: Mar 24 jun | E3: HU12 | F3: Como paciente Quiero poder iniciar sesión en el sistema utilizando mi correo y mi contraseña Para acceder a mi perfil y funcionalidades del sistema médico. | G3: 2 | H3: Alta
C4: Mar 24 jun | D4: Mie 25 jun | E4: HU13 | F4: Como paciente Quiero contar con una opción para recuperar mi contraseña en caso de olvidarla Para poder restablecer mi acceso al sistema. | G4: 5 | H4: Alta
C5: Mie 25 jun | D5: Jue 26 jun | E5: HU11 | F5: Como paciente Quiero recibir un mensaje claro si al intentar iniciar sesión el servidor está caído o hay un problema técnico Para saber que el error no es mío. | G5: 5 | H5: Baja
B6: Validaciones de formularios | C6: Jue 26 jun | D6: Vie 27 jun | E6: HU10 | F6: Como paciente Quiero ser notificado si intento registrar una cuenta con un correo ya existente Para saber que debo iniciar sesión en lugar de crear una nueva cuenta. | G6: 2 | H6: Media
F7: Total de puntos Sprint 1 | G7: =G2+G3+G4+G5+G6 -> 19
A9: Sprint | B9: Objetivo | C9: Fecha Inicio | D9: Fecha Fin | E9: ID HU | F9: Historia de Usuario | G9: Puntos de Historia | H9: Prioridad
A10: Sprint 2 | B10: Menu | C10: Lun 30 jun | D10: Lun 30 jun | E10: HU01 | F10: Como paciente Quiero que el sistema tenga categorías claras en el menú (como “Inicio”, “Agendamiento de citas”, “Mi planilla”, “Familiares”, “Indicaciones médicas”, “Configuración”) Para poder navegar fácilmente sin perderme. | G10: 3 | H10: Alta
B11: Panel principal | C11: Lun 30 jun | D11: Mar 1 jul | E11: HU02 | F11: Como paciente Quiero ver un panel principal con un resumen de mis próximas citas, indicaciones médicas y notificaciones recientes Para tener un panorama general desde que ingreso al sistema. | G11: 5 | H11: Media
C12: Mar 1 jul | D12: Mie 2 jul | E12: HU03 | F12: Como médico Quiero contar con un panel donde pueda visualizar mis citas del día y acceder al historial médico de cada paciente agendado Para preparar mejor mi jornada laboral. | G12: 5 | H12: Alta
B13: Pie de pagina | C13: Mie 2 jul | D13: Mie 2 jul | E13: HU58 | F13: Como paciente Quiero que en cada sección del sistema se muestre un pie de página con la información esencial de la institución Para tener a la mano datos importantes sin importar dónde esté en el sistema. | G13: 2 | H13: Baja
B14: Gestión de Notificaciones | C14: Mie 2 jul | D14: Vie 4 jul | E14: HU41 | F14: Como paciente Quiero recibir una alerta cuando tenga una cita cercana (por ejemplo, un día antes), Para no olvidarla. | G14: 8 | H14: Media
F15: Total de puntos Sprint 2 | G15: =G10+G11+G12+G13+G14 -> 23
A17: Sprint | B17: Objetivo | C17: Fecha Inicio | D17: Fecha Fin | E17: ID HU | F17: Historia de Usuario | G17: Puntos de Historia | H17: Prioridad
A18: Sprint 3 | B18: Gestión de Notificaciones | C18: Lun 7 jul | D18: Lun 7 jul | E18: HU54 | F18: Como paciente Quiero tener una opción visible en todo momento para acceder a mis notificaciones, Para estar informado de cualquier novedad del sistema. | G18: 2 | H18: Baja
C19: Lun 7 jul | D19: Mie 9 jul | E19: HU55 | F19: Como paciente Quiero poder ver en detalle la información de cada notificación o que me redirija a la sección relacionada Para comprender mejor su contenido. | G19: 8 | H19: Baja
C20: Mie 9 jul | D20: Mie 9 jul | E20: HU56 | F20: Como paciente Quiero tener una opción para eliminar notificaciones individuales (por ejemplo, con un ícono de bote de basura) Para mantener limpia mi bandeja de notificaciones. | G20: 3 | H20: Baja
C21: Mie 9 jul | D21: Jue 10 jul | E21: HU57 | F21: Como paciente Quiero tener una opción para eliminar todas mis notificaciones de una sola vez Para ahorrar tiempo y evitar hacerlo una por una. | G21: 2 | H21: Baja
B22: Gestion tecnica | C22: Jue 10 jul | D22: Jue 10 jul | E22: HU04 | F22: Como paciente Quiero tener acceso a un chat de soporte o una sección de preguntas Frecuentes Para recibir ayuda si tengo problemas usando el sistema. | G22: 3 | H22: Baja
C23: Jue 10 jul | D23: Vie 11 jul | E23: HU05 | F23: Como paciente Quiero poder reportar un error técnico desde cualquier pantalla del sistema Para notificar fácilmente si algo no funciona correctamente | G23: 5 | H23: Media
F24: Total de puntos Sprint 3 | G24: =G18+G19+G20+G21+G22+G23 -> 23
A26: Sprint | B26: Objetivo | C26: Fecha Inicio | D26: Fecha Fin | E26: ID HU | F26: Historia de Usuario | G26: Puntos de Historia | H26: Prioridad
A27: Sprint 4 | B27: Perfil | C27: Lun 14 jul | D27: Lun 14 jul | E27: HU51 | F27: Como paciente Quiero tener acceso a un contenedor o menú desplegable desde mi perfil Para gestionar mis opciones personales dentro del sistema. | G27: 3 | H27: Media
C28: Lun 14 jul | D28: Mar 15 jul | E28: HU52 | F28: Como paciente Quiero poder modificar mis datos personales (como teléfono, dirección, correo) desde el menú de perfil Para mantener mi información actualizada. | G28: 5 | H28: Baja
C29: Mar 15 jul | D29: Mie 16 jul | E29: HU53 | F29: Como paciente Quiero poder cerrar sesión desde el contenedor del perfil Para finalizar mi actividad de forma segura. | G29: 3 | H29: Media
B30: Atención al usuario | C30: Mie 16 jul | D30: Jue 17 jul | E30: HU15 | F30: Como paciente Quiero acceder a una sección con instrucciones o videotutoriales sobre el uso del sistema Para aprender cómo navegar correctamente por la plataforma. | G30: 5 | H30: Baja
B31: Notificaciones | C31: Jue 17 jul | D31: Vie 18 jul | E31: HU07 | F31: Como paciente Quiero poder elegir qué tipo de notificaciones deseo recibir (correo) Para evitar recibir información no deseada. | G31: 5 | H31: Baja
F32: Total de puntos Sprint 4 | G32: =G27+G28+G29+G30+G31 -> 21
A34: Sprint | B34: Objetivo | C34: Fecha Inicio | D34: Fecha Fin | E34: ID HU | F34: Historia de Usuario | G34: Puntos de Historia | H34: Prioridad
A35: Sprint 5 | B35: Alertas | C35: Lun 21 jul | D35: Lun 21 jul | E35: HU18 | F35: Como paciente Quiero que el sistema me muestre una notificación si accedo a una página inexistente o rota Para poder volver fácilmente al inicio o a una sección válida | G35: 2 | H35: Baja
C36: Lun 21 jul | D36: Lun 21 jul | E36: HU34 | F36: Como paciente Quiero que el sistema me notifique si no puede cargar la lista de médicos disponibles, Para saber que hay un problema técnico. | G36: 2 | H36: Baja
B37: Novedades | C37: Lun 21 jul | D37: Mar 22 jul | E37: HU14 | F37: Como paciente Quiero ver un apartado con noticias, novedades, proyectos, tutoriales y otras actividades relacionadas con la institución médica Para mantenerme informado. | G37: 5 | H37: Baja
C38: Mar 22 jul | D38: Mar 22 jul | E38: HU17 | F38: Como paciente Quiero que el sistema me muestre un mensaje si las noticias o novedades no se pueden cargar Para saber que no es un error de mi dispositivo. | G38: 2 | H38: Baja
B39: Navegación | C39: Mar 22 jul | D39: Mie 23 jul | E39: HU16 | F39: Como paciente Quiero poder navegar a través del sistema utilizando una miga de pan Para saber en qué sección me encuentro y regresar fácilmente a una anterior. | G39: 2 | H39: Baja
B40: Indicaciones médicas | C40: Mie 23 jul | D40: Mie 23 jul | E40: HU47 | F40: Como paciente Quiero poder visualizar las indicaciones médicas registradas por el profesional de salud tras una cita, como medicamentos o exámenes Para saber con claridad qué debo hacer. | G40: 5 | H40: Alta
C41: Mie 23 jul | D41: Jue 24 jul | E41: HU48 | F41: Como paciente Quiero poder activar notificaciones a partir de un horario definido por mí Para recordar cuándo tomar medicamentos o realizar actividades médicas. | G41: 2 | H41: Alta
C42: Jue 24 jul | D42: Vie 25 jul | E42: HU49 | F42: Como paciente Quiero recibir una notificación clara si el médico aún no ha registrado indicaciones tras una cita Para saber que no es un error del sistema. | G42: 2 | H42: Media
C43: Vie 25 jul | D43: Vie 25 jul | E43: HU50 | F43: Como paciente Quiero poder marcar una indicación como “completada” o “hecha” Para llevar un registro de mi cumplimiento del tratamiento. | G43: 2 | H43: Media
F44: Total de puntos Sprint 5 | G44: =G37+G38+G35+G36+G39+G40+G41+G42+G43 -> 24
...

Sheet Sprint Backlog - 27-06-25
A1: Sprint | B1: Objetivo | C1: Fecha Inicio | D1: Fecha Fin | E1: ID HU | F1: Historia de Usuario | G1: Puntos de Historia | H1: Prioridad
A2: Sprint 1 | B2: Menu | C2: Lun 23 jun | D2: Lun 23 jun | E2: HU01 | F2: Como paciente Quiero que el sistema tenga categorías claras en el menú Para poder navegar fácilmente sin perderme. | G2: 3 | H2: Must-be
B3: Panel principal | C3: Lun 23 jun | D3: Mar 24 jun | E3: HU03 | F3: Como médico Quiero contar con un panel donde pueda visualizar mis citas del día y acceder al historial médico de cada paciente agendado Para preparar mejor mi jornada laboral. | G3: 5 | H3: Must-be
B4: Gestion tecnica | C4: Mar 24 jun | D4: Mie 25 jun | E4: HU05 | F4: Como paciente Quiero poder reportar un error técnico desde cualquier pantalla del sistema Para notificar fácilmente si algo no funciona correctamente | G4: 5 | H4: Must-be
B5: Gestion de horarios | C5: Mie 25 jun | D5: Jue 26 jun | E5: HU06 | F5: Como administrador Quiero poder modificar horarios a los médicos Para que los mismos sepan las modificaciones o actualizaciones sobre el horario | G5: 5 | H5: Must-be
B6: Formulario de registro | C6: Jue 26 jun | D6: Vie 27 jun | E6: HU09 | F6: Como paciente Quiero registrarme mediante un formulario que solicite mis datos personales y de contacto, incluyendo aceptación de términos y condiciones Para poder acceder al sistema con una cuenta propia. | G6: 5 | H6: Must-be
F7: Total de puntos Sprint 1 | G7: =G2+G3+G4+G5+G6 -> 23
A9: Sprint | B9: Objetivo | C9: Fecha Inicio | D9: Fecha Fin | E9: ID HU | F9: Historia de Usuario | G9: Puntos de Historia | H9: Prioridad
A10: Sprint 2 | B10: Formulario de inicio de sesion | C10: Lun 30 jun | D10: Lun 30 jun | E10: HU12 | F10: Como paciente Quiero poder iniciar sesión en el sistema utilizando mi correo y mi contraseña Para acceder a mi perfil y funcionalidades del sistema médico. | G10: 2 | H10: Must-be
C11: Lun 30 jun | D11: Mar 1 jul | E11: HU13 | F11: Como paciente Quiero contar con una opción para recuperar mi contraseña en caso de olvidarla Para poder restablecer mi acceso al sistema. | G11: 5 | H11: Must-be
B12: Gestion de horarios | C12: Mar 1 jul | D12: Mie 2 jul | E12: HU27 | F12: Como administrador Quiero que el sistema valide que las citas solo se puedan agendar dentro del horario laboral Para evitar reservas fuera del tiempo permitido. | G12: 5 | H12: Must-be
C13: Mie 2 jul | D13: Mie 2 jul | E13: HU28 | F13: Como administrador Quiero que se registre cada nueva cita agendada por los pacientes Para llevar control del flujo de atención médica. | G13: 3 | H13: Must-be
B14: Gestion de citas | C14: Mie 2 jul | D14: Vie 4 jul | E14: HU35 | F14: Como paciente Quiero poder cancelar o reprogramar una cita ya agendada Para ajustarla a mis imprevistos o cambios de agenda. | G14: 5 | H14: Must-be
F15: Total de puntos Sprint 2 | G15: =G10+G11+G12+G13+G14 -> 20
A17: Sprint | C17: Fecha Inicio | D17: Fecha Fin | E17: ID HU | F17: Historia de Usuario | G17: Puntos de Historia | H17: Prioridad
A18: Sprint 3 | B18: Gestión de mi planilla | C18: Lun 7 jul | D18: Lun 7 jul | E18: HU42 | F18: Como paciente Quiero tener la opción de modificar o reprogramar una cita desde la sección de “Citas próximas” Para ajustarla si se me presenta un imprevisto. | G18: 3 | H18: Must-be
B19: Indicaciones médicas | C19: Lun 7 jul | D19: Mar 8 jul | E19: HU47 | F19: Como paciente Quiero poder visualizar las indicaciones médicas registradas por el profesional de salud tras una cita, como medicamentos o exámenes Para saber con claridad qué debo hacer. | G19: 5 | H19: Must-be
B20: Perfil | C20: Mar 8 jul | D20: Mie 9 jul | E20: HU51 | F20: Como paciente Quiero tener acceso a un contenedor o menú desplegable desde mi perfil Para gestionar mis opciones personales dentro del sistema. | G20: 3 | H20: Must-be
C21: Mie 9 jul | D21: Jue 10 jul | E21: HU52 | F21: Como paciente Quiero poder modificar mis datos personales (como teléfono, dirección, correo) desde el menú de perfil Para mantener mi información actualizada. | G21: 5 | H21: Must-be
C22: Jue 10 jul | D22: Jue 10 jul | E22: HU53 | F22: Como paciente Quiero poder cerrar sesión desde el contenedor del perfil Para finalizar mi actividad de forma segura. | G22: 3 | H22: Must-be
B23: Pie de pagina | C23: Jue 10 jul | D23: Vie 11 jul | E23: HU58 | F23: Como paciente Quiero que en cada sección del sistema se muestre un pie de página con la información esencial de la institución Para tener a la mano datos importantes sin importar dónde esté en el sistema. | G23: 2 | H23: Must-be
F24: Total de puntos Sprint 3 | G24: =G18+G19+G20+G21+G22+G23 -> 21
A26: Sprint | B26: Objetivo | C26: Fecha Inicio | D26: Fecha Fin | E26: ID HU | F26: Historia de Usuario | G26: Puntos de Historia | H26: Prioridad
A27: Sprint 4 | B27: Panel principal | C27: Lun 14 jul | D27: Mar 15 jul | E27: HU02 | F27: Como paciente Quiero ver un panel principal con un resumen de mis próximas citas, indicaciones médicas y notificaciones recientes Para tener un panorama general desde que ingreso al sistema. | G27: 5 | H27: Performance
B28: Certificado | C28: Mar 15 jul | D28: Mie 16 jul | E28: HU08 | F28: Como paciente Quiero poder descargar o imprimir un comprobante de mi cita médica Para tenerlo disponible si me lo solicitan o lo necesito. | G28: 5 | H28: Performance
B29: Validaciones de formularios | C29: Mie 16 jul | D29: Mie 16 jul | E29: HU10 | F29: Como paciente Quiero ser notificado si intento registrar una cuenta con un correo ya existente Para saber que debo iniciar sesión en lugar de crear una nueva cuenta. | G29: 2 | H29: Performance
B30: Formulario de inicio de sesion | C30: Mie 16 jul | D30: Jue 17 jul | E30: HU11 | F30: Como paciente Quiero recibir un mensaje claro si al intentar iniciar sesión el servidor está caído o hay un problema técnico Para saber que el error no es mío. | G30: 5 | H30: Performance
B31: Navegación | C31: Jue 17 jul | D31: Jue 17 jul | E31: HU16 | F31: Como paciente Quiero poder navegar a través del sistema utilizando una miga de pan Para saber en qué sección me encuentro y regresar fácilmente a una anterior. | G31: 2 | H31: Performance
B32: Novedades | C32: Jue 17 jul | D32: Vie 18 jul | E32: HU17 | F32: Como paciente Quiero que el sistema me muestre un mensaje si las noticias o novedades no se pueden cargar Para saber que no es un error de mi dispositivo. | G32: 2 | H32: Performance
F33: Total de puntos Sprint 4 | G33: =G27+G28+G29+G30+G31+G32 -> 21
A35: Sprint | B35: Objetivo | C35: Fecha Inicio | D35: Fecha Fin | E35: ID HU | F35: Historia de Usuario | G35: Puntos de Historia | H35: Prioridad
A36: Sprint 5 | B36: Alertas | C36: Lun 21 jul | D36: Lun 21 jul | E36: HU18 | F36: Como paciente Quiero que el sistema me muestre una notificación si accedo a una página inexistente o rota Para poder volver fácilmente al inicio o a una sección válida | G36: 2 | H36: Performance
B37: Calendario | C37: Lun 21 jul | D37: Mar 22 jul | E37: HU19 | F37: Como paciente Quiero acceder a un calendario donde pueda ver los días disponibles Para seleccionar cuándo deseo agendar una cita médica. | G37: 5 | H37: Performance
C38: Mar 22 jul | D38: Mar 22 jul | E38: HU20 | F38: Como paciente Quiero ver qué días ya están totalmente ocupados Para evitar seleccionar días sin disponibilidad. | G38: 3 | H38: Performance
B39: Gestion de citas | C39: Mar 22 jul | D39: Mie 23 jul | E39: HU22 | F39: Como paciente Quiero poder filtrar las citas por especialidad médica Para encontrar más fácilmente al profesional que necesito. | G39: 5 | H39: Performance
C40: Mie 23 jul | D40: Vie 25 jul | E40: HU23 | F40: Como paciente Quiero elegir la hora exacta en la que deseo agendar mi cita Para ajustarla a mi disponibilidad. | G40: 8 | H40: Performance
F41: Total de puntos Sprint 5 | G41: =G38+G39+G36+G37+G40 -> 23
A43: Sprint | B43: Objetivo | C43: Fecha Inicio | D43: Fecha Fin | E43: ID HU | F43: Historia de Usuario | G43: Puntos de Historia | H43: Prioridad
A44: Sprint 6 | B44: Gestion de citas | C44: Lun 28 jul | D44: Mar 29 jul | E44: HU24 | F44: Como paciente Quiero poder elegir la sede donde quiero recibir atención médica Para escoger la más cercana o conveniente. | G44: 5 | H44: Performance
B45: Calendario | C45: Mar 29 jul | D45: Mar 29 jul | E45: HU25 | F45: Como paciente Quiero que se me muestren claramente los horarios ya tomados Para no intentar agendar en ellos. | G45: 3 | H45: Performance
...

Sheet Sprint Backlog
A1: Sprint | B1: Objetivo | C1: Fecha Inicio | D1: Fecha Fin | E1: ID HU | F1: Historia de Usuario | G1: Puntos de Historia | H1: Prioridad
A2: Sprint 1 | B2: Menu | C2: Lun 28 jul | D2: Lun 28 jul | E2: HU01 | F2: Como paciente Quiero que el sistema tenga categorías claras en el menú Para poder navegar fácilmente sin perderme. | G2: 3 | H2: Must-be
B3: Panel principal | C3: Lun 28 jul | D3: Mar 29 jul | E3: HU03 | F3: Como médico Quiero contar con un panel donde pueda visualizar mis citas del día y acceder al historial médico de cada paciente agendado Para preparar mejor mi jornada laboral. | G3: 5 | H3: Must-be
B4: Gestion tecnica | C4: Mar 29 jul | D4: Mie 30 jul | E4: HU05 | F4: Como paciente Quiero poder reportar un error técnico desde cualquier pantalla del sistema Para notificar fácilmente si algo no funciona correctamente | G4: 5 | H4: Must-be
B5: Gestion de horarios | C5: Mie 30 jul | D5: Jue 31 jul | E5: HU06 | F5: Como administrador Quiero poder modificar horarios a los médicos Para que los mismos sepan las modificaciones o actualizaciones sobre el horario | G5: 5 | H5: Must-be
B6: Formulario de registro | C6: Jue 31 jul | D6: Vie 1 ago | E6: HU09 | F6: Como paciente Quiero registrarme mediante un formulario que solicite mis datos personales y de contacto, incluyendo aceptación de términos y condiciones Para poder acceder al sistema con una cuenta propia. | G6: 5 | H6: Must-be
F7: Total de puntos Sprint 1 | G7: =G2+G3+G4+G5+G6 -> 23
A9: Sprint | B9: Objetivo | C9: Fecha Inicio | D9: Fecha Fin | E9: ID HU | F9: Historia de Usuario | G9: Puntos de Historia | H9: Prioridad
A10: Sprint 2 | B10: Formulario de inicio de sesion | C10: Lun 4 ago | D10: Lun 4 ago | E10: HU12 | F10: Como paciente Quiero poder iniciar sesión en el sistema utilizando mi correo y mi contraseña Para acceder a mi perfil y funcionalidades del sistema médico. | G10: 2 | H10: Must-be
C11: Lun 4 ago | D11: Mar 5 ago | E11: HU13 | F11: Como paciente Quiero contar con una opción para recuperar mi contraseña en caso de olvidarla Para poder restablecer mi acceso al sistema. | G11: 5 | H11: Must-be
B12: Gestion de horarios | C12: Mar 5 ago | D12: Mie 6 ago | E12: HU27 | F12: Como administrador Quiero que el sistema valide que las citas solo se puedan agendar dentro del horario laboral Para evitar reservas fuera del tiempo permitido. | G12: 5 | H12: Must-be
C13: Mie 6 ago | D13: Jue 7 ago | E13: HU28 | F13: Como administrador Quiero que se registre cada nueva cita agendada por los pacientes Para llevar control del flujo de atención médica. | G13: 3 | H13: Must-be
B14: Gestion de citas | C14: Jue 7 ago | D14: Vie 8 ago | E14: HU35 | F14: Como paciente Quiero poder cancelar o reprogramar una cita ya agendada Para ajustarla a mis imprevistos o cambios de agenda. | G14: 5 | H14: Must-be
F15: Total de puntos Sprint 2 | G15: =G10+G11+G12+G13+G14 -> 20
A17: Sprint | C17: Fecha Inicio | D17: Fecha Fin | E17: ID HU | F17: Historia de Usuario | G17: Puntos de Historia | H17: Prioridad
A18: Sprint 3 | B18: Gestión de mi planilla | C18: Lun 11 ago | D18: Lun 11 ago | E18: HU42 | F18: Como paciente Quiero tener la opción de modificar o reprogramar una cita desde la sección de “Citas próximas” Para ajustarla si se me presenta un imprevisto. | G18: 3 | H18: Must-be
B19: Indicaciones médicas | C19: Lun 11 ago | D19: Mar 12 ago | E19: HU47 | F19: Como paciente Quiero poder visualizar las indicaciones médicas registradas por el profesional de salud tras una cita, como medicamentos o exámenes Para saber con claridad qué debo hacer. | G19: 5 | H19: Must-be
B20: Perfil | C20: Mar 12 ago | D20: Mie 13 ago | E20: HU51 | F20: Como paciente Quiero tener acceso a un contenedor o menú desplegable desde mi perfil Para gestionar mis opciones personales dentro del sistema. | G20: 3 | H20: Must-be
C21: Mie 13 ago | D21: Jue 14 ago | E21: HU52 | F21: Como paciente Quiero poder modificar mis datos personales (como teléfono, dirección, correo) desde el menú de perfil Para mantener mi información actualizada. | G21: 5 | H21: Must-be
C22: Jue 14 ago | D22: Jue 14 ago | E22: HU53 | F22: Como paciente Quiero poder cerrar sesión desde el contenedor del perfil Para finalizar mi actividad de forma segura. | G22: 3 | H22: Must-be
B23: Gestion de usuarios | C23: Jue 14 ago | D23: Vie 15 ago | E23: HU59 | F23: Como administrador Quiero una sección para poder agregar usuarios (medicos, pacientes, y administradores) | G23: 2 | H23: Must-be
F24: Total de puntos Sprint 3 | G24: =G18+G19+G20+G21+G22+G23 -> 21
A26: Sprint | B26: Objetivo | C26: Fecha Inicio | D26: Fecha Fin | E26: ID HU | F26: Historia de Usuario | G26: Puntos de Historia | H26: Prioridad
A27: Sprint 4 | B27: Pie de pagina | C27: Lun 18 ago | D27: Lun 18 ago | E27: HU58 | F27: Como paciente Quiero que en cada sección del sistema se muestre un pie de página con la información esencial de la institución Para tener a la mano datos importantes sin importar dónde esté en el sistema. | G27: 2 | H27: Must-be
B28: Panel principal | C28: Lun 18 ago | D28: Mar 19 ago | E28: HU02 | F28: Como paciente Quiero ver un panel principal con un resumen de mis próximas citas, indicaciones médicas y notificaciones recientes Para tener un panorama general desde que ingreso al sistema. | G28: 5 | H28: Performance
B29: Certificado | C29: Mar 19 ago | D29: Mie 20 ago | E29: HU08 | F29: Como paciente Quiero poder descargar o imprimir un comprobante de mi cita médica Para tenerlo disponible si me lo solicitan o lo necesito. | G29: 5 | H29: Performance
B30: Validaciones de formularios | C30: Mie 20 ago | D30: Mie 20 ago | E30: HU10 | F30: Como paciente Quiero ser notificado si intento registrar una cuenta con un correo ya existente Para saber que debo iniciar sesión en lugar de crear una nueva cuenta. | G30: 2 | H30: Performance
B31: Formulario de inicio de sesion | C31: Mie 20 ago | D31: Jue 21 ago | E31: HU11 | F31: Como paciente Quiero recibir un mensaje claro si al intentar iniciar sesión el servidor está caído o hay un problema técnico Para saber que el error no es mío. | G31: 5 | H31: Performance
B32: Navegación | C32: Jue 21 ago | D32: Jue 21 ago | E32: HU16 | F32: Como paciente Quiero poder navegar a través del sistema utilizando una miga de pan Para saber en qué sección me encuentro y regresar fácilmente a una anterior. | G32: 2 | H32: Performance
B33: Novedades | C33: Jue 21 ago | D33: Vie 22 ago | E33: HU17 | F33: Como paciente Quiero que el sistema me muestre un mensaje si las noticias o novedades no se pueden cargar Para saber que no es un error de mi dispositivo. | G33: 2 | H33: Performance
F34: Total de puntos Sprint 4 | G34: =G27+G28+G29+G30+G31+G32+G33 -> 23
A36: Sprint | B36: Objetivo | C36: Fecha Inicio | D36: Fecha Fin | E36: ID HU | F36: Historia de Usuario | G36: Puntos de Historia | H36: Prioridad
B37: Alertas | C37: Lun 25 ago | D37: Lun 25 ago | E37: HU18 | F37: Como paciente Quiero que el sistema me muestre una notificación si accedo a una página inexistente o rota Para poder volver fácilmente al inicio o a una sección válida | G37: 2 | H37: Performance
B38: Calendario | C38: Lun 25 ago | D38: Mar 26 ago | E38: HU19 | F38: Como paciente Quiero acceder a un calendario donde pueda ver los días disponibles Para seleccionar cuándo deseo agendar una cita médica. | G38: 5 | H38: Performance
C39: Mar 26 ago | D39: Mie 27 ago | E39: HU20 | F39: Como paciente Quiero ver qué días ya están totalmente ocupados Para evitar seleccionar días sin disponibilidad. | G39: 3 | H39: Performance
B40: Gestion de citas | C40: Mie 27 ago | D40: Jue 28 ago | E40: HU22 | F40: Como paciente Quiero poder filtrar las citas por especialidad médica Para encontrar más fácilmente al profesional que necesito. | G40: 5 | H40: Performance
C41: Jue 28 ago | D41: Vie 29 ago | E41: HU23 | F41: Como paciente Quiero elegir la hora exacta en la que deseo agendar mi cita Para ajustarla a mi disponibilidad. | G41: 8 | H41: Performance
F42: Total de puntos Sprint 4 | G42: =G37+G38+G39+G40+G41 -> 23
A44: Sprint | B44: Objetivo | C44: Fecha Inicio | D44: Fecha Fin | E44: ID HU | F44: Historia de Usuario | G44: Puntos de Historia | H44: Prioridad
A45: Sprint 6 | B45: Gestion de citas | C45: Lun 1 sep | D45: Mar 2 sep | E45: HU24 | F45: Como paciente Quiero poder elegir la sede donde quiero recibir atención médica Para escoger la más cercana o conveniente. | G45: 5 | H45: Performance
...

Sheet Tareas X Sprint - Antiguo
A1: SPRINT 1
A2: ID HU | B2: Título resumido | C2: Tarea | D2: Responsable | E2: Horas estimadas | F2: Entregable | G2: Horas totales
A3: HU09 | B3: Registro de nuevo usuario | C3: Diseño del formulario de registro con campos necesarios y mensaje de términos | D3: Diseñador | E3: 3 | F3: Formulario de registro funcional con validacion de datos | G3: ='Sprint Backlog - Antiguo'!G2*4 -> 20
C4: Desarrollo de formulario de registro | D4: Frontend | E4: 6
C5: Creación de usuarios, validación de datos y almacenamiento seguro | D5: Backend | E5: 8
C6: Pruebas de validación del formulario y funcionalidad de registro | D6: QA | E6: 2
C7: Revisión conjunta del flujo de registro | D7: Todos | E7: 1
A8: HU12 | B8: Validación de campos del formulario en tiempo real | C8: Tarea | D8: Responsable | E8: Horas estimadas | F8: Entregable | G8: Horas totales
C9: Definir reglas de validación para cada campo (formato, longitud, requeridos, etc...) | D9: Diseñador | E9: 4 | F9: Formulario con validación en tiempo real y mensajes de error útiles | G9: ='Sprint Backlog - Antiguo'!G3*4 -> 8
C10: Implementar validación en tiempo real durante la escritura en el formulario, crear mensajes de error claros y accesibles para cada tipo de validación | D10: Frontend | E10: 6
D11: Backend
C12: Verificar funcionamiento de todas las validaciones (manual y automatizado) | D12: QA | E12: 1
C13: Revisión de flujo completo de registro con validaciones activas | D13: Todos | E13: 1
A14: HU13 | B14: Recuperacion de contraseña | C14: Tarea | D14: Responsable | E14: Horas estimadas | F14: Entregable | G14: Horas totales
C15: Definir la política de seguridad (longitud mínima, caracteres especiales, etc.) | D15: Diseñador | E15: 2 | F15: Registro validado con contraseñas seguras según política definida | G15: ='Sprint Backlog - Antiguo'!G4*4 -> 20
C16: Implementar validación de contraseña según política en el formulario de registro | D16: Frontend | E16: 3
C17: Agregar validación del lado del servidor y mensajes de errores claros | D17: Backend | E17: 5
C18: Verificar funcionamiento con casos válidos e inválidos | D18: QA | E18: 1
C19: Revisión conjunta del cumplimiento y experiencia de usuario | D19: Todos | E19: 1
A20: HU11 | B20: Notificación por error del servidor en inicio de sesión | C20: Tarea | D20: Responsable | E20: Horas estimadas | F20: Entregable | G20: Horas totales
C21: Diseño de mensaje de error claro y empático | D21: Diseñador | E21: 2 | F21: Error técnico mostrado adecuadamente al usuario final si el sistema falla. | G21: ='Sprint Backlog - Antiguo'!G5*4 -> 20
C22: Visualización del mensaje de error en pantalla de login | D22: Frontend | E22: 6
C23: Implementación del manejo de errores del servidor al iniciar sesión | D23: Backend | E23: 8
C24: Pruebas simulando error del servidor | D24: QA | E24: 3
C25: Revisión integral del flujo | D25: Todos | E25: 1
A26: HU10 | B26: Alerta por correo duplicado en registro | C26: Tarea | D26: Responsable | E26: Horas estimadas | F26: Entregable | G26: Horas totales
C27: Diseño del mensaje de advertencia cuando el correo ya está registrado | D27: Diseñador | E27: 1 | F27: Mensaje desplegado correctamente al detectar correo ya registrado, indicando iniciar sesión en su lugar. | G27: ='Sprint Backlog - Antiguo'!G6*4 -> 8
C28: Integración del mensaje de advertencia en la interfaz | D28: Frontend | E28: 2
C29: Implementación de validación de correo en base de datos | D29: Backend | E29: 3
C30: Pruebas con correos duplicados y verificación de la notificación | D30: QA | E30: 1
C31: Revisión conjunta de la funcionalidad | D31: Todos | E31: 1
A33: SPRINT 2
A34: ID HU | B34: Título resumido | C34: Tarea | D34: Responsable | E34: Horas estimadas | F34: Entregable | G34: Horas totales
A35: HU01 | B35: Menú de navegación clara | C35: Diseño de estructura del menú con categorías visibles y comprensibles | D35: Diseñador | E35: 3 | F35: Menú funcional con las categorías: Inicio, Agendamiento de citas, Mi planilla, Familiares, Indicaciones médicas, Configuración. | G35: ='Sprint Backlog - Antiguo'!G10*4 -> 12
C36: Desarrollo del menú interactivo (menú lateral o superior) | D36: Frontend | E36: 3
C37: Configuración lógica de navegación y rutas hacia cada sección | D37: Backend | E37: 3
C38: Pruebas de usabilidad para asegurar que cada categoría lleva al lugar correcto | D38: QA | E38: 2
C39: Revisión de accesibilidad y facilidad de uso | D39: Todos | E39: 1
A40: HU02 | B40: Panel de resumen del paciente | C40: Tarea | D40: Responsable | E40: Horas estimadas | F40: Entregable | G40: Horas totales
C41: Diseño de la interfaz del panel con bloques para citas, indicaciones y notificaciones | D41: Diseñador | E41: 2 | F41: Panel integrado que muestra citas próximas, indicaciones médicas activas y notificaciones recientes. | G41: ='Sprint Backlog - Antiguo'!G11*4 -> 20
...

Sheet Tareas X Sprint 27-06-25
A1: SPRINT 1
A2: ID HU | B2: Título resumido | C2: Tarea | D2: Responsable | E2: Horas estimadas | F2: Entregable | G2: Horas totales
A3: HU01 | B3: Menú de navegación clara | C3: Diseño de estructura del menú con categorías visibles y comprensibles | D3: Diseñador | E3: 3 | F3: Menú funcional con las categorías: Inicio, Agendamiento de citas, Mi planilla, Familiares, Indicaciones médicas, Configuración. | G3: ='Sprint Backlog - 27-06-25'!$G$2*4 -> 12
C4: Desarrollo del menú interactivo (menú lateral o superior) | D4: Frontend | E4: 3
C5: Configuración lógica de navegación y rutas hacia cada sección | D5: Backend | E5: 3
C6: Pruebas de usabilidad para asegurar que cada categoría lleva al lugar correcto | D6: QA | E6: 2
C7: Revisión de accesibilidad y facilidad de uso | D7: Todos | E7: 1
A8: HU03 | B8: Panel diario del médico | C8: Tarea | D8: Responsable | E8: Horas estimadas | F8: Entregable | G8: Horas totales
